Traceback (most recent call last):
  File "notifications.py", line 51, in <module>
    for user in users:
  File "/usr/local/lib/python2.7/dist-packages/pymongo/cursor.py", line 1114, in next
    if len(self.__data) or self._refresh():
  File "/usr/local/lib/python2.7/dist-packages/pymongo/cursor.py", line 1036, in _refresh
    self.__collation))
  File "/usr/local/lib/python2.7/dist-packages/pymongo/cursor.py", line 873, in __send_message
    **kwargs)
  File "/usr/local/lib/python2.7/dist-packages/pymongo/mongo_client.py", line 888, in _send_message_with_response
    server = topology.select_server(selector)
  File "/usr/local/lib/python2.7/dist-packages/pymongo/topology.py", line 214, in select_server
    address))
  File "/usr/local/lib/python2.7/dist-packages/pymongo/topology.py", line 189, in select_servers
    self._error_message(selector))
pymongo.errors.ServerSelectionTimeoutError: 127.0.0.1:8080: [Errno 111] Connection refused
Traceback (most recent call last):
  File "notifications.py", line 51, in <module>
    for user in users:
  File "/usr/local/lib/python2.7/dist-packages/pymongo/cursor.py", line 1114, in next
    if len(self.__data) or self._refresh():
  File "/usr/local/lib/python2.7/dist-packages/pymongo/cursor.py", line 1036, in _refresh
    self.__collation))
  File "/usr/local/lib/python2.7/dist-packages/pymongo/cursor.py", line 873, in __send_message
    **kwargs)
  File "/usr/local/lib/python2.7/dist-packages/pymongo/mongo_client.py", line 905, in _send_message_with_response
    exhaust)
  File "/usr/local/lib/python2.7/dist-packages/pymongo/mongo_client.py", line 916, in _reset_on_error
    return func(*args, **kwargs)
  File "/usr/local/lib/python2.7/dist-packages/pymongo/server.py", line 99, in send_message_with_response
    with self.get_socket(all_credentials, exhaust) as sock_info:
  File "/usr/lib/python2.7/contextlib.py", line 17, in __enter__
    return self.gen.next()
  File "/usr/local/lib/python2.7/dist-packages/pymongo/server.py", line 168, in get_socket
    with self.pool.get_socket(all_credentials, checkout) as sock_info:
  File "/usr/lib/python2.7/contextlib.py", line 17, in __enter__
    return self.gen.next()
  File "/usr/local/lib/python2.7/dist-packages/pymongo/pool.py", line 790, in get_socket
    sock_info = self._get_socket_no_auth()
  File "/usr/local/lib/python2.7/dist-packages/pymongo/pool.py", line 836, in _get_socket_no_auth
    sock_info = self._check(sock_info)
  File "/usr/local/lib/python2.7/dist-packages/pymongo/pool.py", line 890, in _check
    return self.connect()
  File "/usr/local/lib/python2.7/dist-packages/pymongo/pool.py", line 763, in connect
    _raise_connection_failure(self.address, error)
  File "/usr/local/lib/python2.7/dist-packages/pymongo/pool.py", line 211, in _raise_connection_failure
    raise AutoReconnect(msg)
pymongo.errors.AutoReconnect: 127.0.0.1:8080: [Errno 111] Connection refused
Traceback (most recent call last):
  File "notifications.py", line 51, in <module>
    for user in users:
  File "/usr/local/lib/python2.7/dist-packages/pymongo/cursor.py", line 1114, in next
    if len(self.__data) or self._refresh():
  File "/usr/local/lib/python2.7/dist-packages/pymongo/cursor.py", line 1036, in _refresh
    self.__collation))
  File "/usr/local/lib/python2.7/dist-packages/pymongo/cursor.py", line 873, in __send_message
    **kwargs)
  File "/usr/local/lib/python2.7/dist-packages/pymongo/mongo_client.py", line 905, in _send_message_with_response
    exhaust)
  File "/usr/local/lib/python2.7/dist-packages/pymongo/mongo_client.py", line 916, in _reset_on_error
    return func(*args, **kwargs)
  File "/usr/local/lib/python2.7/dist-packages/pymongo/server.py", line 99, in send_message_with_response
    with self.get_socket(all_credentials, exhaust) as sock_info:
  File "/usr/lib/python2.7/contextlib.py", line 17, in __enter__
    return self.gen.next()
  File "/usr/local/lib/python2.7/dist-packages/pymongo/server.py", line 168, in get_socket
    with self.pool.get_socket(all_credentials, checkout) as sock_info:
  File "/usr/lib/python2.7/contextlib.py", line 17, in __enter__
    return self.gen.next()
  File "/usr/local/lib/python2.7/dist-packages/pymongo/pool.py", line 790, in get_socket
    sock_info = self._get_socket_no_auth()
  File "/usr/local/lib/python2.7/dist-packages/pymongo/pool.py", line 836, in _get_socket_no_auth
    sock_info = self._check(sock_info)
  File "/usr/local/lib/python2.7/dist-packages/pymongo/pool.py", line 890, in _check
    return self.connect()
  File "/usr/local/lib/python2.7/dist-packages/pymongo/pool.py", line 763, in connect
    _raise_connection_failure(self.address, error)
  File "/usr/local/lib/python2.7/dist-packages/pymongo/pool.py", line 211, in _raise_connection_failure
    raise AutoReconnect(msg)
pymongo.errors.AutoReconnect: 127.0.0.1:8080: [Errno 111] Connection refused
Traceback (most recent call last):
  File "notifications.py", line 51, in <module>
    for user in users:
  File "/usr/local/lib/python2.7/dist-packages/pymongo/cursor.py", line 1114, in next
    if len(self.__data) or self._refresh():
  File "/usr/local/lib/python2.7/dist-packages/pymongo/cursor.py", line 1036, in _refresh
    self.__collation))
  File "/usr/local/lib/python2.7/dist-packages/pymongo/cursor.py", line 873, in __send_message
    **kwargs)
  File "/usr/local/lib/python2.7/dist-packages/pymongo/mongo_client.py", line 905, in _send_message_with_response
    exhaust)
  File "/usr/local/lib/python2.7/dist-packages/pymongo/mongo_client.py", line 916, in _reset_on_error
    return func(*args, **kwargs)
  File "/usr/local/lib/python2.7/dist-packages/pymongo/server.py", line 99, in send_message_with_response
    with self.get_socket(all_credentials, exhaust) as sock_info:
  File "/usr/lib/python2.7/contextlib.py", line 17, in __enter__
    return self.gen.next()
  File "/usr/local/lib/python2.7/dist-packages/pymongo/server.py", line 168, in get_socket
    with self.pool.get_socket(all_credentials, checkout) as sock_info:
  File "/usr/lib/python2.7/contextlib.py", line 17, in __enter__
    return self.gen.next()
  File "/usr/local/lib/python2.7/dist-packages/pymongo/pool.py", line 790, in get_socket
    sock_info = self._get_socket_no_auth()
  File "/usr/local/lib/python2.7/dist-packages/pymongo/pool.py", line 836, in _get_socket_no_auth
    sock_info = self._check(sock_info)
  File "/usr/local/lib/python2.7/dist-packages/pymongo/pool.py", line 890, in _check
    return self.connect()
  File "/usr/local/lib/python2.7/dist-packages/pymongo/pool.py", line 763, in connect
    _raise_connection_failure(self.address, error)
  File "/usr/local/lib/python2.7/dist-packages/pymongo/pool.py", line 211, in _raise_connection_failure
    raise AutoReconnect(msg)
pymongo.errors.AutoReconnect: 127.0.0.1:8080: [Errno 111] Connection refused
Traceback (most recent call last):
  File "notifications.py", line 51, in <module>
    for user in users:
  File "/usr/local/lib/python2.7/dist-packages/pymongo/cursor.py", line 1114, in next
    if len(self.__data) or self._refresh():
  File "/usr/local/lib/python2.7/dist-packages/pymongo/cursor.py", line 1036, in _refresh
    self.__collation))
  File "/usr/local/lib/python2.7/dist-packages/pymongo/cursor.py", line 873, in __send_message
    **kwargs)
  File "/usr/local/lib/python2.7/dist-packages/pymongo/mongo_client.py", line 888, in _send_message_with_response
    server = topology.select_server(selector)
  File "/usr/local/lib/python2.7/dist-packages/pymongo/topology.py", line 214, in select_server
    address))
  File "/usr/local/lib/python2.7/dist-packages/pymongo/topology.py", line 189, in select_servers
    self._error_message(selector))
pymongo.errors.ServerSelectionTimeoutError: 127.0.0.1:8080: [Errno 111] Connection refused
